Workbook

Sheet Synthèse
A1: SMARTFIN — Synthèse financière
A2: Vue d'ensemble pour investisseurs et partenaires (M FCFA sauf mention contraire)
A4: Indicateur clé | B4: Unité | C4: 2027 | D4: 2028 | E4: 2029 | F4: 2030 | G4: 2031
A5: Inscrits en fin d'année | B5: clients | C5: =Projections!C6 -> 25000 | D5: =Projections!D6 -> 90000 | E5: =Projections!E6 -> 220000 | F5: =Projections!F6 -> 400000 | G5: =Projections!G6 -> 650000
A6: Clients actifs | B6: clients | C6: =Projections!C9 -> 4375 | D6: =Projections!D9 -> 23000 | E6: =Projections!E9 -> 69750 | F6: =Projections!F9 -> 148800 | G6: =Projections!G9 -> 262500
A7: Dépôts annuels | B7: M FCFA | C7: =Projections!C12 -> 1050000000 | D7: =Projections!D12 -> 6072000000 | E7: =Projections!E12 -> 20925000000 | F7: =Projections!F12 -> 48211200000 | G7: =Projections!G12 -> 94500000000
A8: Encours moyen clients | B8: M FCFA | C8: =Projections!C15 -> 109375000 | D8: =Projections!D15 -> 690000000 | E8: =Projections!E15 -> 2441250000 | F8: =Projections!F15 -> 5952000000 | G8: =Projections!G15 -> 11812500000
A9: Chiffre d'affaires | B9: M FCFA | C9: =Projections!C25 -> 12908438 | D9: =Projections!D25 -> 94438000 | E9: =Projections!E25 -> 372744000 | F9: =Projections!F25 -> 939270240 | G9: =Projections!G25 -> 1936593750
A10: Marge brute | B10: M FCFA | C10: =Projections!C33 -> -8751562.5 | D10: =Projections!D33 -> 298000 | E10: =Projections!E33 -> 98052750 | F10: =Projections!F33 -> 364632480 | G10: =Projections!G33 -> 942993750
A11: Taux de marge brute | B11: % | C11: =Projections!C34 -> -0.67797226 | D11: =Projections!D34 -> 0.0031555094 | E11: =Projections!E34 -> 0.26305655 | F11: =Projections!F34 -> 0.38820828 | G11: =Projections!G34 -> 0.48693421
A12: EBITDA | B12: M FCFA | C12: =Projections!C45 -> -1.5637656e+08 | D12: =Projections!D45 -> -273802000 | E12: =Projections!E45 -> -368953250 | F12: =Projections!F45 -> -288943520 | G12: =Projections!G45 -> 78909750
A13: Résultat net | B13: M FCFA | C13: =Projections!C50 -> -1.7704323e+08 | D13: =Projections!D50 -> -2.9446867e+08 | E13: =Projections!E50 -> -3.8961992e+08 | F13: =Projections!F50 -> -288943520 | G13: =Projections!G50 -> 59182312
A14: Trésorerie cumulée (hors levée) | B14: M FCFA | C14: =Projections!C54 -> -2.1837656e+08 | D14: =Projections!D54 -> -4.9217856e+08 | E14: =Projections!E54 -> -8.6113181e+08 | F14: =Projections!F54 -> -1.1500753e+09 | G14: =Projections!G54 -> -1090893020
A15: Revenu par actif | B15: FCFA | C15: =Projections!C57 -> 2950.5 | D15: =Projections!D57 -> 4106 | E15: =Projections!E57 -> 5344 | F15: =Projections!F57 -> 6312.3 | G15: =Projections!G57 -> 7377.5
A16: Ratio LTV / CAC | B16: x | C16: =Projections!C62 -> -1.40025 | D16: =Projections!D62 -> 0.011959866 | E16: =Projections!E62 -> 1.581496 | F16: =Projections!F62 -> 3.2079104 | G16: =Projections!G62 -> 5.3885357
A18: Chiffres clés
A19: Besoin de financement (creux de trésorerie) | B19: =-MIN(0,MIN(Projections!$C$54:$G$54)) -> 1.1500753e+09 | C19: Montant minimal à lever avant marge de sécurité ; prévoir +30 %.
A20: Levée recommandée (besoin + 30 % de sécurité) | B20: =B19*1.3 -> 1.4950979e+09
A21: Première année d'EBITDA positif | B21: =IFERROR(INDEX(Projections!$C$4:$G$4,MATCH(1,Projections!$C$55:$G$55,0)),"Après 2031") -> 2031
A22: Chiffre d'affaires cumulé sur 5 ans | B22: =SUM(Projections!$C$25:$G$25) -> 3.3559544e+09
A23: Investissements de lancement | B23: =Investissement!$B$11 -> 62000000
A25: Lecture : l'équilibre dépend surtout (1) du coût d'encaissement négocié avec les opérateurs, (2) de l'encours moyen par client (revenus du float) et (3) de la conversion SMARTFIN+. Voir l'onglet Sensibilité et les cellules jaunes de l'onglet Hypothèses.

Sheet Hypothèses
A1: SMARTFIN — Hypothèses du modèle
A2: Cellules bleues = saisies modifiables · fond jaune = hypothèses clés · montants en FCFA
A3: Légende : modifiez uniquement les cellules en bleu ; tous les autres onglets se recalculent. Une valeur seule en colonne C s'applique aux 5 années.
A5: Hypothèse | B5: Unité | C5: 2027 | D5: 2028 | E5: 2029 | F5: 2030 | G5: 2031 | H5: Commentaire / source
A6: Clients
A7: Inscrits en fin d'année | B7: clients | C7: 25000 | D7: 90000 | E7: 220000 | F7: 400000 | G7: 650000 | H7: Hypothèse de lancement : Abidjan A1, toute la Côte d'Ivoire A2, Sénégal + Burkina A3, reste UEMOA A4-A5.
A8: Taux d'actifs mensuels (sur inscrits moyens) | B8: % | C8: 0.35 | D8: 0.4 | E8: 0.45 | F8: 0.48 | G8: 0.5 | H8: Part des inscrits ayant au moins une opération dans le mois. Référence fintechs d'épargne : 30-50 %.
A9: Actifs abonnés SMARTFIN+ | B9: % | C9: 0.03 | D9: 0.05 | E9: 0.07 | F9: 0.08 | G9: 0.09 | H9: Conversion freemium typique : 2-10 % des actifs.
A10: Flux d'argent
A11: Dépôt moyen mensuel par actif | B11: FCFA | C11: 20000 | D11: 22000 | E11: 25000 | F11: 27000 | G11: 30000 | H11: Montant épargné/transité chaque mois via l'app (pas le salaire complet).
A12: Part des dépôts retirée vers Mobile Money | B12: % | C12: 0.45 | H12: Le reste est épargné (e-caisse, projets, challenges, cagnottes) ou transféré entre utilisateurs.
A13: Part des retraits offerts (SMARTFIN+) | B13: % | C13: 0.1 | H13: 3 retraits offerts par mois aux abonnés.
A14: Encours moyen par actif | B14: FCFA | C14: 25000 | D14: 30000 | E14: 35000 | F14: 40000 | G14: 45000 | H14: Solde moyen portefeuille + épargne bloquée.
A15: Part des dépôts passant par une Cagnotte+ | B15: % | C15: 0.15 | D15: 0.18 | E15: 0.2 | F15: 0.2 | G15: 0.2 | H15: Tontines et épargne de groupe.
A16: Part de l'encours en e-caisse | B16: % | C16: 0.3
A17: Part des e-caisses cassées avant l'échéance (par an) | B17: % | C17: 0.15
A18: Tarifs (alignés sur backend/src/pricing.ts)
A19: Frais de retrait | B19: % | C19: 0.015 | H19: 1,5 % (min. 100 F, max. 7 500 F).
A20: Frais de retrait Cagnotte+ | B20: % | C20: 0.01
A21: Pénalité de rupture e-caisse | B21: % | C21: 0.02
A22: Abonnement SMARTFIN+ mensuel | B22: FCFA | C22: 1000
A23: Rendement annuel du float (compte de cantonnement / DAT) | B23: % | C23: 0.03 | H23: À valider avec la banque partenaire : la rémunération des fonds de monnaie électronique est encadrée par la BCEAO.
A24: Commissions partenaires par actif et par an | B24: FCFA | C24: 0 | D24: 500 | E24: 1000 | F24: 1500 | G24: 2000 | H24: Apport d'affaires : micro-assurance, microcrédit (IMF), épargne rémunérée partenaire.
A25: Coûts directs
A26: Coût d'encaissement (agrégateur / opérateurs) | B26: % | C26: 0.01 | D26: 0.009 | E26: 0.008 | F26: 0.008 | G26: 0.007 | H26: Grille indicative agrégateurs UEMOA 1-2 % ; objectif : contrats directs Wave / Orange / MTN < 1 %. HYPOTHÈSE CRITIQUE.
A27: Coût de décaissement (payout) | B27: % | C27: 0.006 | D27: 0.005 | E27: 0.005 | F27: 0.004 | G27: 0.004 | H27: À négocier.
A28: SMS par actif et par mois (OTP, alertes) | B28: SMS | C28: 2 | H28: Réduire via notifications push.
A29: Coût unitaire SMS | B29: FCFA | C29: 15
A30: Part des nouveaux inscrits vérifiés (KYC) | B30: % | C30: 0.4
A31: Coût d'une vérification KYC | B31: FCFA | C31: 300 | H31: Vérification pièce + selfie (prestataire).
A32: Part des nouveaux inscrits venus par parrainage | B32: % | C32: 0.3
A33: Bonus parrain | B33: FCFA | C33: 500 | H33: Versé au 1er dépôt ≥ 5 000 F.
A34: Charges d'exploitation
A35: Effectif (ETP moyen) | B35: personnes | C35: 8 | D35: 14 | E35: 22 | F35: 32 | G35: 42 | H35: Tech, produit, conformité, support, ventes/ambassadeurs.
A36: Coût moyen annuel chargé par ETP | B36: FCFA | C36: 7200000 | D36: 7560000 | E36: 7938000 | F36: 8335000 | G36: 8752000 | H36: 600 000 F/mois chargés en A1, +5 %/an.
A37: Coût d'acquisition par nouvel inscrit (CAC) | B37: FCFA | C37: 1500 | D37: 1300 | E37: 1200 | F37: 1100 | G37: 1000 | H37: Réseaux sociaux, influenceurs, ambassadeurs, activations terrain. Baisse avec le parrainage et la notoriété.
A38: Marketing de marque (fixe) | B38: FCFA | C38: 15000000 | D38: 30000000 | E38: 50000000 | F38: 70000000 | G38: 90000000
A39: Infrastructure cloud (fixe) | B39: FCFA | C39: 6000000 | D39: 9000000 | E39: 15000000 | F39: 22000000 | G39: 30000000
A40: Infrastructure par actif et par an | B40: FCFA | C40: 120
A41: Banque / EME partenaire (frais annuels) | B41: FCFA | C41: 12000000 | D41: 15000000 | E41: 20000000 | F41: 25000000 | G41: 30000000 | H41: Tenue du compte de cantonnement et partenariat monnaie électronique.
...

Sheet Investissement
A1: SMARTFIN — Budget de lancement
A2: Investissements et dépenses avant/au démarrage (FCFA)
A4: Poste | B4: Montant (FCFA) | C4: Commentaire
A5: Développement app mobile + API + back-office (finitions, audits) | B5: 25000000 | C5: Base technique livrée dans ce dépôt ; budget de durcissement et d'intégrations opérateurs.
A6: Design UX/UI, identité, contenus tutoriels vidéo | B6: 6000000
A7: Test d'intrusion et audit de sécurité avant lancement | B7: 5000000 | C7: Obligatoire avant d'ouvrir les flux d'argent.
A8: Constitution société, contrats partenaires, conseil réglementaire | B8: 8000000 | C8: Convention avec banque / EME agréé BCEAO, CGU, politique LBC/FT.
A9: Équipement (ordinateurs, téléphones de test) | B9: 6000000 | C9: Amorti sur 3 ans.
A10: Campagne de lancement (événement, influenceurs, affichage) | B10: 12000000
A11: Total investissements de lancement | B11: =SUM(B5:B10) -> 62000000
A12: Durée d'amortissement (années) | B12: 3

Sheet Projections
A1: SMARTFIN — Projections sur 5 ans
A2: Montants en millions de FCFA sauf mention contraire · tout est calculé à partir des hypothèses
A4: Indicateur | B4: Unité | C4: 2027 | D4: 2028 | E4: 2029 | F4: 2030 | G4: 2031 | H4: Méthode de calcul
A5: Clients
A6: Inscrits en fin d'année | B6: clients | C6: =Hypothèses!C7 -> 25000 | D6: =Hypothèses!D7 -> 90000 | E6: =Hypothèses!E7 -> 220000 | F6: =Hypothèses!F7 -> 400000 | G6: =Hypothèses!G7 -> 650000
A7: Inscrits moyens | B7: clients | C7: =C6/2 -> 12500 | D7: =(C6+D6)/2 -> 57500 | E7: =(D6+E6)/2 -> 155000 | F7: =(E6+F6)/2 -> 310000 | G7: =(F6+G6)/2 -> 525000 | H7: (début + fin) / 2
A8: Nouveaux inscrits | B8: clients | C8: =C6 -> 25000 | D8: =D6-C6 -> 65000 | E8: =E6-D6 -> 130000 | F8: =F6-E6 -> 180000 | G8: =G6-F6 -> 250000
A9: Clients actifs (moyenne mensuelle) | B9: clients | C9: =C7*Hypothèses!C8 -> 4375 | D9: =D7*Hypothèses!D8 -> 23000 | E9: =E7*Hypothèses!E8 -> 69750 | F9: =F7*Hypothèses!F8 -> 148800 | G9: =G7*Hypothèses!G8 -> 262500
A10: Abonnés SMARTFIN+ | B10: clients | C10: =C9*Hypothèses!C9 -> 131.25 | D10: =D9*Hypothèses!D9 -> 1150 | E10: =E9*Hypothèses!E9 -> 4882.5 | F10: =F9*Hypothèses!F9 -> 11904 | G10: =G9*Hypothèses!G9 -> 23625
A11: Volumes
A12: Dépôts annuels | B12: M FCFA | C12: =C9*Hypothèses!C11*12 -> 1050000000 | D12: =D9*Hypothèses!D11*12 -> 6072000000 | E12: =E9*Hypothèses!E11*12 -> 20925000000 | F12: =F9*Hypothèses!F11*12 -> 48211200000 | G12: =G9*Hypothèses!G11*12 -> 94500000000 | H12: actifs × dépôt mensuel × 12
A13: Retraits vers Mobile Money | B13: M FCFA | C13: =C12*Hypothèses!$C$12 -> 472500000 | D13: =D12*Hypothèses!$C$12 -> 2732400000 | E13: =E12*Hypothèses!$C$12 -> 9416250000 | F13: =F12*Hypothèses!$C$12 -> 21695040000 | G13: =G12*Hypothèses!$C$12 -> 42525000000
A14: dont retraits payants | B14: M FCFA | C14: =C13*(1-Hypothèses!$C$13) -> 425250000 | D14: =D13*(1-Hypothèses!$C$13) -> 2459160000 | E14: =E13*(1-Hypothèses!$C$13) -> 8474625000 | F14: =F13*(1-Hypothèses!$C$13) -> 19525536000 | G14: =G13*(1-Hypothèses!$C$13) -> 38272500000
A15: Encours moyen clients (float) | B15: M FCFA | C15: =C9*Hypothèses!C14 -> 109375000 | D15: =D9*Hypothèses!D14 -> 690000000 | E15: =E9*Hypothèses!E14 -> 2441250000 | F15: =F9*Hypothèses!F14 -> 5952000000 | G15: =G9*Hypothèses!G14 -> 11812500000
A16: Retraits de Cagnottes+ | B16: M FCFA | C16: =C12*Hypothèses!C15 -> 157500000 | D16: =D12*Hypothèses!D15 -> 1092960000 | E16: =E12*Hypothèses!E15 -> 4185000000 | F16: =F12*Hypothèses!F15 -> 9642240000 | G16: =G12*Hypothèses!G15 -> 18900000000
A17: E-caisses cassées avant l'échéance | B17: M FCFA | C17: =C15*Hypothèses!$C$16*Hypothèses!$C$17 -> 4921875 | D17: =D15*Hypothèses!$C$16*Hypothèses!$C$17 -> 31050000 | E17: =E15*Hypothèses!$C$16*Hypothèses!$C$17 -> 109856250 | F17: =F15*Hypothèses!$C$16*Hypothèses!$C$17 -> 267840000 | G17: =G15*Hypothèses!$C$16*Hypothèses!$C$17 -> 531562500
A18: Revenus
A19: Frais de retrait | B19: M FCFA | C19: =C14*Hypothèses!$C$19 -> 6378750 | D19: =D14*Hypothèses!$C$19 -> 36887400 | E19: =E14*Hypothèses!$C$19 -> 127119375 | F19: =F14*Hypothèses!$C$19 -> 292883040 | G19: =G14*Hypothèses!$C$19 -> 574087500
A20: Frais Cagnotte+ | B20: M FCFA | C20: =C16*Hypothèses!$C$20 -> 1575000 | D20: =D16*Hypothèses!$C$20 -> 10929600 | E20: =E16*Hypothèses!$C$20 -> 41850000 | F20: =F16*Hypothèses!$C$20 -> 96422400 | G20: =G16*Hypothèses!$C$20 -> 189000000
A21: Pénalités e-caisse | B21: M FCFA | C21: =C17*Hypothèses!$C$21 -> 98437.5 | D21: =D17*Hypothèses!$C$21 -> 621000 | E21: =E17*Hypothèses!$C$21 -> 2197125 | F21: =F17*Hypothèses!$C$21 -> 5356800 | G21: =G17*Hypothèses!$C$21 -> 10631250
A22: Abonnements SMARTFIN+ | B22: M FCFA | C22: =C10*Hypothèses!$C$22*12 -> 1575000 | D22: =D10*Hypothèses!$C$22*12 -> 13800000 | E22: =E10*Hypothèses!$C$22*12 -> 58590000 | F22: =F10*Hypothèses!$C$22*12 -> 142848000 | G22: =G10*Hypothèses!$C$22*12 -> 283500000
A23: Revenus du float | B23: M FCFA | C23: =C15*Hypothèses!$C$23 -> 3281250 | D23: =D15*Hypothèses!$C$23 -> 20700000 | E23: =E15*Hypothèses!$C$23 -> 73237500 | F23: =F15*Hypothèses!$C$23 -> 178560000 | G23: =G15*Hypothèses!$C$23 -> 354375000
A24: Commissions partenaires | B24: M FCFA | C24: =C9*Hypothèses!C24 -> 0 | D24: =D9*Hypothèses!D24 -> 11500000 | E24: =E9*Hypothèses!E24 -> 69750000 | F24: =F9*Hypothèses!F24 -> 223200000 | G24: =G9*Hypothèses!G24 -> 525000000
A25: Chiffre d'affaires | B25: M FCFA | C25: =SUM(C19:C24) -> 12908438 | D25: =SUM(D19:D24) -> 94438000 | E25: =SUM(E19:E24) -> 372744000 | F25: =SUM(F19:F24) -> 939270240 | G25: =SUM(G19:G24) -> 1936593750
A26: Coûts directs
A27: Frais d'encaissement opérateurs | B27: M FCFA | C27: =C12*Hypothèses!C26 -> 10500000 | D27: =D12*Hypothèses!D26 -> 54648000 | E27: =E12*Hypothèses!E26 -> 167400000 | F27: =F12*Hypothèses!F26 -> 385689600 | G27: =G12*Hypothèses!G26 -> 661500000
A28: Frais de décaissement opérateurs | B28: M FCFA | C28: =C13*Hypothèses!C27 -> 2835000 | D28: =D13*Hypothèses!D27 -> 13662000 | E28: =E13*Hypothèses!E27 -> 47081250 | F28: =F13*Hypothèses!F27 -> 86780160 | G28: =G13*Hypothèses!G27 -> 170100000
A29: SMS (OTP, alertes) | B29: M FCFA | C29: =C9*Hypothèses!$C$28*12*Hypothèses!$C$29 -> 1575000 | D29: =D9*Hypothèses!$C$28*12*Hypothèses!$C$29 -> 8280000 | E29: =E9*Hypothèses!$C$28*12*Hypothèses!$C$29 -> 25110000 | F29: =F9*Hypothèses!$C$28*12*Hypothèses!$C$29 -> 53568000 | G29: =G9*Hypothèses!$C$28*12*Hypothèses!$C$29 -> 94500000
A30: Vérifications KYC | B30: M FCFA | C30: =C8*Hypothèses!$C$30*Hypothèses!$C$31 -> 3000000 | D30: =D8*Hypothèses!$C$30*Hypothèses!$C$31 -> 7800000 | E30: =E8*Hypothèses!$C$30*Hypothèses!$C$31 -> 15600000 | F30: =F8*Hypothèses!$C$30*Hypothèses!$C$31 -> 21600000 | G30: =G8*Hypothèses!$C$30*Hypothèses!$C$31 -> 30000000
A31: Bonus de parrainage | B31: M FCFA | C31: =C8*Hypothèses!$C$32*Hypothèses!$C$33 -> 3750000 | D31: =D8*Hypothèses!$C$32*Hypothèses!$C$33 -> 9750000 | E31: =E8*Hypothèses!$C$32*Hypothèses!$C$33 -> 19500000 | F31: =F8*Hypothèses!$C$32*Hypothèses!$C$33 -> 27000000 | G31: =G8*Hypothèses!$C$32*Hypothèses!$C$33 -> 37500000
A32: Total coûts directs | B32: M FCFA | C32: =SUM(C27:C31) -> 21660000 | D32: =SUM(D27:D31) -> 94140000 | E32: =SUM(E27:E31) -> 274691250 | F32: =SUM(F27:F31) -> 574637760 | G32: =SUM(G27:G31) -> 993600000
A33: Marge brute | B33: M FCFA | C33: =C25-C32 -> -8751562.5 | D33: =D25-D32 -> 298000 | E33: =E25-E32 -> 98052750 | F33: =F25-F32 -> 364632480 | G33: =G25-G32 -> 942993750
A34: Taux de marge brute | B34: % | C34: =IF(C25=0,0,C33/C25) -> -0.67797226 | D34: =IF(D25=0,0,D33/D25) -> 0.0031555094 | E34: =IF(E25=0,0,E33/E25) -> 0.26305655 | F34: =IF(F25=0,0,F33/F25) -> 0.38820828 | G34: =IF(G25=0,0,G33/G25) -> 0.48693421
A35: Charges d'exploitation
A36: Salaires et charges | B36: M FCFA | C36: =Hypothèses!C35*Hypothèses!C36 -> 57600000 | D36: =Hypothèses!D35*Hypothèses!D36 -> 105840000 | E36: =Hypothèses!E35*Hypothèses!E36 -> 174636000 | F36: =Hypothèses!F35*Hypothèses!F36 -> 266720000 | G36: =Hypothèses!G35*Hypothèses!G36 -> 367584000
A37: Marketing d'acquisition | B37: M FCFA | C37: =C8*Hypothèses!C37 -> 37500000 | D37: =D8*Hypothèses!D37 -> 84500000 | E37: =E8*Hypothèses!E37 -> 156000000 | F37: =F8*Hypothèses!F37 -> 198000000 | G37: =G8*Hypothèses!G37 -> 250000000 | H37: nouveaux inscrits × CAC
A38: Marketing de marque | B38: M FCFA | C38: =Hypothèses!C38 -> 15000000 | D38: =Hypothèses!D38 -> 30000000 | E38: =Hypothèses!E38 -> 50000000 | F38: =Hypothèses!F38 -> 70000000 | G38: =Hypothèses!G38 -> 90000000
A39: Infrastructure cloud | B39: M FCFA | C39: =Hypothèses!C39+C9*Hypothèses!$C$40 -> 6525000 | D39: =Hypothèses!D39+D9*Hypothèses!$C$40 -> 11760000 | E39: =Hypothèses!E39+E9*Hypothèses!$C$40 -> 23370000 | F39: =Hypothèses!F39+F9*Hypothèses!$C$40 -> 39856000 | G39: =Hypothèses!G39+G9*Hypothèses!$C$40 -> 61500000
A40: Banque / EME partenaire | B40: M FCFA | C40: =Hypothèses!C41 -> 12000000 | D40: =Hypothèses!D41 -> 15000000 | E40: =Hypothèses!E41 -> 20000000 | F40: =Hypothèses!F41 -> 25000000 | G40: =Hypothèses!G41 -> 30000000
A41: Juridique, conformité, sécurité | B41: M FCFA | C41: =Hypothèses!C42 -> 10000000 | D41: =Hypothèses!D42 -> 15000000 | E41: =Hypothèses!E42 -> 25000000 | F41: =Hypothèses!F42 -> 30000000 | G41: =Hypothèses!G42 -> 35000000
...

Sheet Sensibilité
A1: SMARTFIN — Sensibilité de l'EBITDA 2029 (M FCFA)
A2: Coût d'encaissement (lignes) × frais de retrait (colonnes), autres hypothèses inchangées
A4: Coût d'encaissement ↓ / Frais de retrait → | B4: 0.01 | C4: 0.0125 | D4: 0.015 | E4: 0.0175 | F4: 0.02
A5: 0.005 | B5: =Projections!$E$45+Projections!$E$14*(B$4-Hypothèses!$C$19)-Projections!$E$12*($A5-Hypothèses!$E$26) -> -348551375 | C5: =Projections!$E$45+Projections!$E$14*(C$4-Hypothèses!$C$19)-Projections!$E$12*($A5-Hypothèses!$E$26) -> -3.2736481e+08 | D5: =Projections!$E$45+Projections!$E$14*(D$4-Hypothèses!$C$19)-Projections!$E$12*($A5-Hypothèses!$E$26) -> -306178250 | E5: =Projections!$E$45+Projections!$E$14*(E$4-Hypothèses!$C$19)-Projections!$E$12*($A5-Hypothèses!$E$26) -> -2.8499169e+08 | F5: =Projections!$E$45+Projections!$E$14*(F$4-Hypothèses!$C$19)-Projections!$E$12*($A5-Hypothèses!$E$26) -> -263805125
A6: 0.0065 | B6: =Projections!$E$45+Projections!$E$14*(B$4-Hypothèses!$C$19)-Projections!$E$12*($A6-Hypothèses!$E$26) -> -379938875 | C6: =Projections!$E$45+Projections!$E$14*(C$4-Hypothèses!$C$19)-Projections!$E$12*($A6-Hypothèses!$E$26) -> -3.5875231e+08 | D6: =Projections!$E$45+Projections!$E$14*(D$4-Hypothèses!$C$19)-Projections!$E$12*($A6-Hypothèses!$E$26) -> -337565750 | E6: =Projections!$E$45+Projections!$E$14*(E$4-Hypothèses!$C$19)-Projections!$E$12*($A6-Hypothèses!$E$26) -> -3.1637919e+08 | F6: =Projections!$E$45+Projections!$E$14*(F$4-Hypothèses!$C$19)-Projections!$E$12*($A6-Hypothèses!$E$26) -> -295192625
A7: 0.008 | B7: =Projections!$E$45+Projections!$E$14*(B$4-Hypothèses!$C$19)-Projections!$E$12*($A7-Hypothèses!$E$26) -> -411326375 | C7: =Projections!$E$45+Projections!$E$14*(C$4-Hypothèses!$C$19)-Projections!$E$12*($A7-Hypothèses!$E$26) -> -3.9013981e+08 | D7: =Projections!$E$45+Projections!$E$14*(D$4-Hypothèses!$C$19)-Projections!$E$12*($A7-Hypothèses!$E$26) -> -368953250 | E7: =Projections!$E$45+Projections!$E$14*(E$4-Hypothèses!$C$19)-Projections!$E$12*($A7-Hypothèses!$E$26) -> -3.4776669e+08 | F7: =Projections!$E$45+Projections!$E$14*(F$4-Hypothèses!$C$19)-Projections!$E$12*($A7-Hypothèses!$E$26) -> -326580125
A8: 0.01 | B8: =Projections!$E$45+Projections!$E$14*(B$4-Hypothèses!$C$19)-Projections!$E$12*($A8-Hypothèses!$E$26) -> -453176375 | C8: =Projections!$E$45+Projections!$E$14*(C$4-Hypothèses!$C$19)-Projections!$E$12*($A8-Hypothèses!$E$26) -> -4.3198981e+08 | D8: =Projections!$E$45+Projections!$E$14*(D$4-Hypothèses!$C$19)-Projections!$E$12*($A8-Hypothèses!$E$26) -> -410803250 | E8: =Projections!$E$45+Projections!$E$14*(E$4-Hypothèses!$C$19)-Projections!$E$12*($A8-Hypothèses!$E$26) -> -3.8961669e+08 | F8: =Projections!$E$45+Projections!$E$14*(F$4-Hypothèses!$C$19)-Projections!$E$12*($A8-Hypothèses!$E$26) -> -368430125
A9: 0.015 | B9: =Projections!$E$45+Projections!$E$14*(B$4-Hypothèses!$C$19)-Projections!$E$12*($A9-Hypothèses!$E$26) -> -557801375 | C9: =Projections!$E$45+Projections!$E$14*(C$4-Hypothèses!$C$19)-Projections!$E$12*($A9-Hypothèses!$E$26) -> -5.3661481e+08 | D9: =Projections!$E$45+Projections!$E$14*(D$4-Hypothèses!$C$19)-Projections!$E$12*($A9-Hypothèses!$E$26) -> -515428250 | E9: =Projections!$E$45+Projections!$E$14*(E$4-Hypothèses!$C$19)-Projections!$E$12*($A9-Hypothèses!$E$26) -> -4.9424169e+08 | F9: =Projections!$E$45+Projections!$E$14*(F$4-Hypothèses!$C$19)-Projections!$E$12*($A9-Hypothèses!$E$26) -> -473055125
A11: Les valeurs de l'intersection surlignée correspondent au scénario central de l'onglet Projections.
